<?xml version ="1.0"?>
<robot name="robot2">

  <link name= "base_link">
    <visual>
      <geometry>
        <box size="0.1 0.1 0.5"/>
      </geometry>
      <material name="lilac">
        <color rgba="0.3 0.1 0.5 1"/>
      </material>
    </visual>
    <collision>
			<geometry>
				<box size="0.1 0.1 0.25"/>
			</geometry>
		</collision>
  </link>

  <link name="arm_link">
    <visual>
      <geometry>
        <box size="0.5 0.1 0.1"/>
      </geometry>
      <material name="lilac">
        <color rgba= "0.3 0.1 0.5 1"/>
      </material>
    </visual>
    <collision>
			<geometry>
				<box size="0.1 0.1 0.25"/>
			</geometry>
		</collision>
  </link>

  <link name= "l1">
  </link>

  <link name="l2">
  </link>

  <joint name="joint1" type="fixed">
    <parent link="l1"/>
    <child link="base_link"/>
    <axis xyz="0 0 1"/>
  </joint>

  <joint name="joint2" type="continuous">
    <parent link="base_link"/>
    <child link="l2"/>
    <axis xyz= "0 0 1"/>
  </joint>

  <joint name= "joint3" type="revolute">
    <parent link="l2"/>
    <child link="arm_link"/>
    <axis xyz="0 0 1"/>
    <origin rpy="0 0 0" xyz="0.1 0.1 0.2"/>
    <limit effort="1000" velocity="5" lower="0" upper="1.5"/>
  </joint>

</robot>
